<?xml version="1.0" encoding="utf-8"?>
<!-- =================================================================================== -->
<!-- |    This document was autogenerated by xacro from panda_arm_hand.urdf.xacro      | -->
<!-- |    EDITING THIS FILE BY HAND IS NOT RECOMMENDED                                 | -->
<!-- =================================================================================== -->
<robot name="panda" xmlns:xacro="http://www.ros.org/wiki/xacro">
  <link name="x">
  </link>
  <link name="y">
  </link>
  <link name="z">
  </link>
  <link name="roll">
  </link>
  <link name="pitch">
  </link>
  <link name="yaw">
  </link>
  <link name="panda_hand">
    <visual>
      <geometry>
        <mesh filename="franka_description/meshes/visual/hand.dae"/>
      </geometry>
    </visual>
    <collision>
      <geometry>
        <mesh filename="franka_description/meshes/collision/hand.stl"/>
      </geometry>
    </collision>
  </link>
  <link name="panda_leftfinger">
    <visual>
      <geometry>
        <mesh filename="franka_description/meshes/visual/finger.dae"/>
      </geometry>
    </visual>
    <collision>
      <geometry>
        <mesh filename="franka_description/meshes/collision/finger.stl"/>
      </geometry>
    </collision>
  </link>
  <link name="panda_rightfinger">
    <visual>
      <origin rpy="0 0 3.14159265359" xyz="0 0 0"/>
      <geometry>
        <mesh filename="franka_description/meshes/visual/finger.dae"/>
      </geometry>
    </visual>
    <collision>
      <origin rpy="0 0 3.14159265359" xyz="0 0 0"/>
      <geometry>
        <mesh filename="franka_description/meshes/collision/finger.stl"/>
      </geometry>
    </collision>
  </link>
  <joint name="joint_x" type="prismatic">
    <parent link="x"/>
    <child link="y"/>
    <origin rpy="0 0 0" xyz="0 0 0.0"/>
    <axis xyz="1 0 0"/>
    <dynamics damping="0.0" friction="0.0"/>
    <limit effort="20" lower="-10." upper="10." velocity="0.2"/>
  </joint>
  <joint name="joint_y" type="prismatic">
    <parent link="y"/>
    <child link="z"/>
    <origin rpy="0 0 0" xyz="0 0 0.0"/>
    <axis xyz="0 1 0"/>
    <dynamics damping="0.0" friction="0.0"/>
    <limit effort="20" lower="-10." upper="10." velocity="0.2"/>
  </joint>
  <joint name="joint_z" type="prismatic">
    <parent link="z"/>
    <child link="roll"/>
    <origin rpy="0 0 0" xyz="0 0 0.0"/>
    <axis xyz="0 0 1"/>
    <dynamics damping="0.0" friction="0.0"/>
    <limit effort="20" lower="-10." upper="10." velocity="0.2"/>
  </joint>
  <joint name="joint_roll" type="fixed">
    <parent link="roll"/>
    <child link="pitch"/>
    <origin rpy="3.141592653589793 0 0" xyz="0 0 0.0"/>
    <axis xyz="1 0 0"/>
    <dynamics damping="0.0" friction="0.0"/>
    <limit effort="20" velocity="0.2"/>
  </joint>
  <joint name="joint_pitch" type="fixed">
    <parent link="pitch"/>
    <child link="yaw"/>
    <origin rpy="0 0 0" xyz="0 0 0.0"/>
    <axis xyz="0 1 0"/>
    <dynamics damping="0.0" friction="0.0"/>
    <limit effort="20" velocity="0.2"/>
  </joint>

  <joint name="joint_yaw" type="fixed">
    <parent link="yaw"/>
    <child link="panda_hand"/>
    <origin rpy="0 0 1.5707963267948966" xyz="0 0 0.0"/>
    <axis xyz="0 0 1"/>
    <dynamics damping="0.0" friction="0.0"/>
    <limit effort="20" velocity="0.2"/>
  </joint>

  <joint name="panda_finger_joint1" type="prismatic">
    <parent link="panda_hand"/>
    <child link="panda_leftfinger"/>
    <origin rpy="0 0 0" xyz="0 0 0.0584"/>
    <axis xyz="0 1 0"/>
    <limit effort="20" lower="0.0" upper="0.04" velocity="0.2"/>
  </joint>
  <joint name="panda_finger_joint2" type="prismatic">
    <parent link="panda_hand"/>
    <child link="panda_rightfinger"/>
    <origin rpy="0 0 0" xyz="0 0 0.0584"/>
    <axis xyz="0 -1 0"/>
    <limit effort="20" lower="0.0" upper="0.04" velocity="0.2"/>
    <mimic joint="panda_finger_joint1"/>
  </joint>
</robot>
