<?xml version="1.0" encoding="utf-8"?>
<robot
  name="xmate3gripper">
  <material name="black">
    <color rgba="0.0 0.0 0.0 1.0"/>
  </material>
  <material name="blue">
    <color rgba="0.0 0.0 0.8 1.0"/>
  </material>
  <material name="green">
    <color rgba="0.0 0.8 0.0 1.0"/>
  </material>
  <material name="grey">
    <color rgba="0.2 0.2 0.2 1.0"/>
  </material>
  <material name="orange">
    <color rgba="1.0 0.423529411765 0.0392156862745 1.0"/>
  </material>
  <material name="brown">
    <color rgba="0.870588235294 0.811764705882 0.764705882353 1.0"/>
  </material>
  <material name="red">
    <color rgba="0.8 0.0 0.0 1.0"/>
  </material>
  <material name="white">
    <color rgba="1.0 1.0 1.0 1.0"/>
  </material>
  <material name="Beige">
    <color rgba="1.0 0.784 0.5765 1.0"/>
  </material>
  <material name="aluminum">
    <color rgba="0.5 0.5 0.5 1"/>
  </material>
  <material name="plastic">
    <color rgba="0.1 0.1 0.1 1"/>
  </material>
  <!-- xmate3_base -->
  <link name="world">
  <inertial>
    <mass value="1"/>
    <inertia ixx="0.04" ixy="0.00" ixz="0.00" iyy="0.04" iyz="0.00" izz="0.02"/>
  </inertial>
  </link>
  <joint name="xmate3_base_joint" type="fixed">
    <origin rpy="0 0 0" xyz="0 0 0"/>
    <parent link="world"/>
    <child link="xmate3_base"/>
  </joint>
  <!--base-->
  <link name="xmate3_base">
    <visual>
      <geometry>
        <mesh filename="xmate3_description/meshes/visual/xmate3_base.stl" scale="0.001 0.001 0.001"/>
      </geometry>
      <origin rpy="0 0 0" xyz="0 0 0"/>
      <material name="white"/>
    </visual>
    <inertial>
      <mass value="5.48267"/>
      <inertia ixx="0.056" ixy="0" ixz="0" iyy="0.066" iyz="0" izz="0.035"/>
      <origin rpy="0 0 0" xyz="-0.0183 0 0.067"/>
    </inertial>
    <collision>
      <geometry>
        <mesh filename="xmate3_description/meshes/collision/xmate3_base.stl" scale="0.001 0.001 0.001"/>
      </geometry>
      <origin rpy="0 0 0" xyz="0.0 0.0 0.0"/>
    </collision>
  </link>
  <joint name="joint1" type="revolute">
    <parent link="xmate3_base"/>
    <child link="xmate3_link1"/>
    <limit effort="300" lower="-3.0527" upper="3.0527" velocity="10"/>
    <axis xyz="0 0 1"/>
    <origin rpy="0 0 0" xyz="0 0 0"/>
  </joint>
  <transmission name="tran1">
    <type>transmission_interface/SimpleTransmission</type>
    <joint name="joint1">
      <hardwareInterface>EffortJointInterface</hardwareInterface>
    </joint>
    <actuator name="motor1">
      <hardwareInterface>EffortJointInterface</hardwareInterface>
      <mechanicalReduction>1</mechanicalReduction>
    </actuator>
  </transmission>
  <!--link 1-->
  <link name="xmate3_link1">
    <visual>
      <geometry>
        <mesh filename="xmate3_description/meshes/visual/xmate3_link1.stl" scale="0.001 0.001 0.001"/>
      </geometry>
      <origin rpy="0 0 0" xyz="0 0 0"/>
      <material name="white"/>
    </visual>
    <inertial>
      <mass value="3.37289"/>
      <inertia ixx="0.314" ixy="0" ixz="0" iyy="0.310" iyz="0" izz="0.01"/>
      <origin rpy="0 0 0" xyz="0 -0.023 0.295"/>
    </inertial>
    <collision>
      <geometry>
        <mesh filename="xmate3_description/meshes/collision/xmate3_link1.stl" scale="0.001 0.001 0.001"/>
      </geometry>
      <origin rpy="0 0 0" xyz="0 0 0"/>
    </collision>
  </link>
  <joint name="joint2" type="revolute">
    <parent link="xmate3_link1"/>
    <child link="xmate3_link2"/>
    <limit effort="300" lower="-2.0933" upper="2.0933" velocity="10"/>
    <axis xyz="0 1 0"/>
    <origin rpy="0 0 0" xyz="0 0 0.34260487"/>
  </joint>
  <transmission name="tran2">
    <type>transmission_interface/SimpleTransmission</type>
    <joint name="joint2">
      <hardwareInterface>EffortJointInterface</hardwareInterface>
    </joint>
    <actuator name="motor2">
      <hardwareInterface>EffortJointInterface</hardwareInterface>
      <mechanicalReduction>1</mechanicalReduction>
    </actuator>
  </transmission>
  <!--link 2-->
  <link name="xmate3_link2">
    <visual>
      <geometry>
        <mesh filename="xmate3_description/meshes/visual/xmate3_link2.stl" scale="0.001 0.001 0.001"/>
      </geometry>
      <origin rpy="0 0 0" xyz="0 0 0.0"/>
      <material name="white"/>
    </visual>
    <inertial>
      <mass value="3.74765"/>
      <inertia ixx="0.074" ixy="0" ixz="0" iyy="0.067" iyz="0" izz="0.014"/>
      <origin rpy="0 0 0" xyz="0 0.032 0.095"/>
    </inertial>
    <collision>
      <geometry>
        <mesh filename="xmate3_description/meshes/collision/xmate3_link2.stl" scale="0.001 0.001 0.001"/>
      </geometry>
      <origin rpy="0 0 0" xyz="0 0 0.0"/>
    </collision>
  </link>
  <joint name="joint3" type="revolute">
    <parent link="xmate3_link2"/>
    <child link="xmate3_link3"/>
    <limit effort="300" lower="-3.0527" upper="3.0527" velocity="10"/>
    <axis xyz="0 0 1"/>
    <origin rpy="0 0 0" xyz="0 0 0.23743878"/>
  </joint>
  <transmission name="tran3">
    <type>transmission_interface/SimpleTransmission</type>
    <joint name="joint3">
      <hardwareInterface>EffortJointInterface</hardwareInterface>
    </joint>
    <actuator name="motor3">
      <hardwareInterface>EffortJointInterface</hardwareInterface>
      <mechanicalReduction>1</mechanicalReduction>
    </actuator>
  </transmission>
  <!--link 3-->
  <link name="xmate3_link3">
    <visual>
      <geometry>
        <mesh filename="xmate3_description/meshes/visual/xmate3_link3.stl" scale="0.001 0.001 0.001"/>
      </geometry>
      <origin rpy="0 0 0" xyz="0 0 0.15549959"/>
      <material name="white"/>
    </visual>
    <inertial>
      <mass value="3.38216"/>
      <inertia ixx="0.028" ixy="0" ixz="0" iyy="0.025" iyz="0" izz="0.01"/>
      <origin rpy="0 0 0" xyz="0 -0.023 -0.048"/>
    </inertial>
    <collision>
      <geometry>
        <mesh filename="xmate3_description/meshes/visual/xmate3_link3.stl" scale="0.001 0.001 0.001"/>
      </geometry>
      <origin rpy="0 0 0" xyz="0 0 0.15549959"/>
    </collision>
  </link>
  <joint name="joint4" type="revolute">
    <parent link="xmate3_link3"/>
    <child link="xmate3_link4"/>
   <limit effort="300" lower="-2.0933" upper="2.0933" velocity="10"/>
<!--     lower="-2.79" upper="2.79" -->
    <axis xyz="0 1 0"/>
<!--     <origin rpy="0 0 0" xyz="0.585 0.0 0.035"/> -->
    <origin rpy="0 0 0" xyz="0 0 0.15549959"/>
  </joint>
  <transmission name="tran4">
    <type>transmission_interface/SimpleTransmission</type>
    <joint name="joint4">
      <hardwareInterface>EffortJointInterface</hardwareInterface>
    </joint>
    <actuator name="motor4">
      <hardwareInterface>EffortJointInterface</hardwareInterface>
      <mechanicalReduction>1</mechanicalReduction>
    </actuator>
  </transmission>
  <!--link 4-->
  <link name="xmate3_link4">
    <visual>
      <geometry>
        <mesh filename="xmate3_description/meshes/visual/xmate3_link4.stl" scale=".001 0.001 0.001"/>
      </geometry>
      <origin rpy="0 0 0" xyz="0.0 0.0 0.0"/>
      <material name="white"/>
    </visual>
    <inertial>
      <mass value="3.21031"/>
      <inertia ixx="0.027" ixy="0" ixz="0" iyy="0.024" iyz="0" izz="0.007"/>
      <origin rpy="0 0 0" xyz="0 0.037 0.075"/>
    </inertial>
    <collision>
      <geometry>
        <mesh filename="xmate3_description/meshes/collision/xmate3_link4.stl" scale="0.001 0.001 0.001"/>
      </geometry>
      <origin rpy="0 0 0" xyz="0.0 0.0 0.0"/>
    </collision>
  </link>
  <joint name="joint5" type="revolute">
    <parent link="xmate3_link4"/>
    <child link="xmate3_link5"/>
    <limit effort="300" lower="-3.0527" upper="3.0527" velocity="10"/>
    <axis xyz="0 0 1"/>
    <origin rpy="0 0 0" xyz="0 0 0.22044633"/>
  </joint>
  <transmission name="tran5">
    <type>transmission_interface/SimpleTransmission</type>
    <joint name="joint5">
      <hardwareInterface>EffortJointInterface</hardwareInterface>
    </joint>
    <actuator name="motor5">
      <hardwareInterface>EffortJointInterface</hardwareInterface>
      <mechanicalReduction>1</mechanicalReduction>
    </actuator>
  </transmission>
  <!--link 5-->
  <link name="xmate3_link5">
    <visual>
      <geometry>
        <mesh filename="xmate3_description/meshes/visual/xmate3_link5.stl" scale="0.001 0.001 0.001"/>
      </geometry>
      <origin rpy="0 0 0" xyz="0 0 0.14512568"/>
      <material name="white"/>
    </visual>
    <inertial>
      <mass value="1.7"/>
      <inertia ixx="0.022" ixy="0" ixz="0" iyy="0.018" iyz="0" izz="0.0076"/>
      <origin rpy="0 0 0" xyz="0 -0.025 -0.052"/>
    </inertial>
    <collision>
      <geometry>
        <mesh filename="xmate3_description/meshes/collision/xmate3_link5.stl" scale="0.001 0.001 0.001"/>
      </geometry>
      <origin rpy="0 0 0" xyz="0 0 0.14512568"/>
    </collision>
  </link>
  <joint name="joint6" type="revolute">
    <parent link="xmate3_link5"/>
    <child link="xmate3_link6"/>
    <limit effort="300" lower="-2.0933" upper="2.0933" velocity="10"/>
    <axis xyz="0 1 0"/>
    <origin xyz="0 0 0.14512568" rpy="0.0 0.0 0.0" />
  </joint>
  <transmission name="tran6">
    <type>transmission_interface/SimpleTransmission</type>
    <joint name="joint6">
      <hardwareInterface>EffortJointInterface</hardwareInterface>
    </joint>
    <actuator name="motor6">
      <hardwareInterface>EffortJointInterface</hardwareInterface>
      <mechanicalReduction>1</mechanicalReduction>
    </actuator>
  </transmission>
  <!--link 6-->
  <link name="xmate3_link6">
    <visual>
      <geometry>
        <mesh filename="xmate3_description/meshes/visual/xmate3_link6.stl" scale="0.001 0.001 0.001"/>
      </geometry>
      <origin rpy="0 0 0" xyz="0.0 0.0 0.0"/>
      <material name="white"/>
    </visual>
    <inertial>
      <mass value="2.6002"/>
      <inertia ixx="0.016" ixy="-0.000000" ixz="-0.000000" iyy="0.0156" iyz="-0.000000" izz="0.0042"/>
      <origin rpy="0 0 0" xyz="0 0.02 0.073"/>
    </inertial>
    <collision>
      <geometry>
        <mesh filename="xmate3_description/meshes/collision/xmate3_link6.stl" scale="0.001 0.001 0.001"/>
      </geometry>
      <origin rpy="0 0 0" xyz="0.0 0.0 0.0"/>
    </collision>
  </link>
  <joint name="joint7" type="revolute">
    <parent link="xmate3_link6"/>
    <child link="xmate3_link7"/>
    <limit effort="300" lower="-6.283" upper="2.993" velocity="10"/>
    <axis xyz="0 0 1"/>
    <origin xyz="0 0 0.25090877" rpy="0.0 0.0 0.0" />
  </joint>
  <transmission name="tran7">
    <type>transmission_interface/SimpleTransmission</type>
    <joint name="joint7">
      <hardwareInterface>EffortJointInterface</hardwareInterface>
    </joint>
    <actuator name="motor7">
      <hardwareInterface>EffortJointInterface</hardwareInterface>
      <mechanicalReduction>1</mechanicalReduction>
    </actuator>
  </transmission>
<!--link 7-->
  <link name="xmate3_link7">
    <visual>
      <geometry>
        <mesh filename="xmate3_description/meshes/visual/xmate3_link7.stl" scale="0.001 0.001 0.001"/>
      </geometry>
      <origin rpy="0 0 0" xyz="0.0 0.0 0"/>
      <material name="white"/>
    </visual>
    <inertial>
      <mass value="1.50517"/>
      <inertia ixx="0.0037" ixy="0" ixz="0" iyy="0.0021" iyz="0" izz="0.0030"/>
      <origin rpy="0 0 0" xyz="0 0.023 -0.044"/>
    </inertial>
    <collision>
      <geometry>
        <mesh filename="xmate3_description/meshes/collision/xmate3_link7.stl" scale="0.001 0.001 0.001"/>
      </geometry>
      <origin rpy="0 0 0" xyz="0.0 0.0 0"/>
    </collision>
  </link>
<!--robotiq adjusted gripper-->
  <link
    name="gripper_connector">
    <inertial>
      <origin
        xyz="-0.0011437 0.013539 0.0070148"
        rpy="0 0 0" />
      <mass
        value="0.17371" />
      <inertia
        ixx="0.00015634"
        ixy="-2.6899E-06"
        ixz="-3.7656E-07"
        iyy="5.565E-05"
        iyz="1.4996E-06"
        izz="0.00020436" />
    </inertial>
    <visual>
      <origin
        xyz="0 0 0"
        rpy="0 0 0" />
      <geometry>
        <mesh
          filename="xmate3_description/meshes/robotiq_connector.STL" />
      </geometry>
      <material
        name="">
        <color
          rgba="0.89804 0.91765 0.92941 1" />
      </material>
    </visual>
    <collision>
      <origin
        xyz="0 0 0"
        rpy="0 0 0" />
      <geometry>
        <mesh
          filename="xmate3_description/meshes/robotiq_connector.STL" />
      </geometry>
    </collision>
  </link>
  <joint
    name="gripper_connector_joint"
    type="fixed">
    <origin
      xyz="0 0 0"
      rpy="0 0 0" />
    <parent
      link="xmate3_link7" />
    <child
      link="gripper_connector" />
    <axis
      xyz="0 0 0" />
  </joint>
  <joint
    name="gripper_connector_joint2"
    type="fixed">
    <origin
      xyz="0 0 0.017"
      rpy="0 0 -1.5708" />
    <parent
      link="gripper_connector" />
    <child
      link="gripper_base_link" />
    <axis
      xyz="0 0 0" />
  </joint>


  <!--  Begin 4DoF Gripper-->
  <link
    name="gripper_base_link">
    <inertial>
      <origin
        xyz="-3.68665581099305E-06 9.14934312396757E-06 0.0286326536554218"
        rpy="0 0 0" />
      <mass
        value="0.836495323590987" />
      <inertia
        ixx="0.0010133968867622"
        ixy="-5.09925546040607E-08"
        ixz="1.18559207019959E-10"
        iyy="0.000547775576154519"
        iyz="-1.91971032593648E-10"
        izz="0.00118440225586729" />
    </inertial>
    <visual>
      <origin
        xyz="0 0 0"
        rpy="0 0 0" />
      <geometry>
        <mesh
          filename="4dof_gripper_description/meshes/base_link.STL" />
      </geometry>
      <material
        name="">
        <color
          rgba="0.898039215686275 0.917647058823529 0.929411764705882 1" />
      </material>
    </visual>
    <collision>
      <origin
        xyz="0 0 0"
        rpy="0 0 0" />
      <geometry>
        <mesh
          filename="4dof_gripper_description/meshes/base_link.STL" />
      </geometry>
    </collision>
  </link>
  <link
    name="Left_1_Link">
    <inertial>
      <origin
        xyz="0.0183900545364742 0 -0.00300000000000008"
        rpy="0 0 0" />
      <mass
        value="0.00570739398759208" />
      <inertia
        ixx="1.14086084728988E-07"
        ixy="-5.7985014611235E-22"
        ixz="-4.18483433557912E-23"
        iyy="1.94766973538297E-06"
        iyz="4.85536245073514E-24"
        izz="2.0532679152074E-06" />
    </inertial>
    <visual>
      <origin
        xyz="0 0 0"
        rpy="0 0 0" />
      <geometry>
        <mesh
          filename="4dof_gripper_description/meshes/Left_1_Link.STL" />
      </geometry>
      <material
        name="">
        <color
          rgba="0.898039215686275 0.917647058823529 0.929411764705882 1" />
      </material>
    </visual>
    <collision>
      <origin
        xyz="0 0 0"
        rpy="0 0 0" />
      <geometry>
        <mesh
          filename="4dof_gripper_description/meshes/Left_1_Link.STL" />
      </geometry>
    </collision>
  </link>
  <joint
    name="Left_1"
    type="revolute">
    <origin
      xyz="0.0014963 0.052806 0.047"
      rpy="0 -1.5708 0" />
    <parent
      link="gripper_base_link" />
    <child
      link="Left_1_Link" />
    <axis
      xyz="0 0 1" />
    <limit
      lower="-3.1416"
      upper="3.1416"
      effort="0"
      velocity="0" />
  </joint>
  <link
    name="Left_2_Link">
    <inertial>
      <origin
        xyz="0.00289936289635065 0.0248358974766605 1.84352088449656E-05"
        rpy="0 0 0" />
      <mass
        value="0.00657030740340087" />
      <inertia
        ixx="9.40189869841171E-07"
        ixy="-1.56093391665658E-07"
        ixz="-5.3466704799694E-14"
        iyy="1.77897148230384E-07"
        iyz="-2.43032697985935E-13"
        izz="1.03664567424634E-06" />
    </inertial>
    <visual>
      <origin
        xyz="0 0 0"
        rpy="0 0 0" />
      <geometry>
        <mesh
          filename="4dof_gripper_description/meshes/Left_2_Link.STL" />
      </geometry>
      <material
        name="">
        <color
          rgba="0.866666666666667 0.866666666666667 0.890196078431372 1" />
      </material>
    </visual>
    <collision>
      <origin
        xyz="0 0 0"
        rpy="0 0 0" />
      <geometry>
        <mesh
          filename="4dof_gripper_description/meshes/Left_2_Link.STL" />
      </geometry>
    </collision>
  </link>
  <joint
    name="Left_2"
    type="revolute">
    <origin
      xyz="0.05 0 0"
      rpy="3.1416 0 1.5708" />
    <parent
      link="Left_1_Link" />
    <child
      link="Left_2_Link" />
    <axis
      xyz="0 0 1" />
    <limit
      lower="-3.1416"
      upper="3.1416"
      effort="0"
      velocity="0" />
  </joint>
  <link
    name="L_TouchSensor_link">
    <inertial>
      <origin
        xyz="0.00202376595001497 -2.12603213266748E-07 -0.0264861041562324"
        rpy="0 0 0" />
      <mass
        value="0.124388957693126" />
      <inertia
        ixx="3.22977251728854E-05"
        ixy="-1.32183136100206E-14"
        ixz="8.25543029410062E-07"
        iyy="3.61487480611385E-05"
        iyz="-2.20679024877823E-13"
        izz="3.00247512991207E-05" />
    </inertial>
    <visual>
      <origin
        xyz="0 0 0"
        rpy="0 0 0" />
      <geometry>
        <mesh
          filename="4dof_gripper_description/meshes/L_TouchSensor_link.STL" />
      </geometry>
      <material
        name="">
        <color
          rgba="0.898039215686275 0.917647058823529 0.929411764705882 1" />
      </material>
    </visual>
    <collision>
      <origin
        xyz="0 0 0"
        rpy="0 0 0" />
      <geometry>
        <mesh
          filename="4dof_gripper_description/meshes/L_TouchSensor_link.STL" />
      </geometry>
    </collision>
  </link>
  <joint
    name="L_TouchSensor"
    type="fixed">
    <origin
      xyz="0.020167 0.067069 0"
      rpy="1.5708 0 -2.618" />
    <parent
      link="Left_2_Link" />
    <child
      link="L_TouchSensor_link" />
    <axis
      xyz="0 0 0" />
  </joint>
  <link
    name="Right_1_Link">
    <inertial>
      <origin
        xyz="0.0183900545364742 0 -0.00299999999999927"
        rpy="0 0 0" />
      <mass
        value="0.00570739398759207" />
      <inertia
        ixx="1.14086084728987E-07"
        ixy="-1.50374058416966E-22"
        ixz="8.29617591803157E-23"
        iyy="1.94766973538297E-06"
        iyz="-1.61022287973713E-24"
        izz="2.0532679152074E-06" />
    </inertial>
    <visual>
      <origin
        xyz="0 0 0"
        rpy="0 0 0" />
      <geometry>
        <mesh
          filename="4dof_gripper_description/meshes/Right_1_Link.STL" />
      </geometry>
      <material
        name="">
        <color
          rgba="0.898039215686275 0.917647058823529 0.929411764705882 1" />
      </material>
    </visual>
    <collision>
      <origin
        xyz="0 0 0"
        rpy="0 0 0" />
      <geometry>
        <mesh
          filename="4dof_gripper_description/meshes/Right_1_Link.STL" />
      </geometry>
    </collision>
  </link>
  <joint
    name="Right_1"
    type="revolute">
    <origin
      xyz="0.00149634448815223 -0.0527936076528706 0.047"
      rpy="0 -1.5707963267949 0" />
    <parent
      link="gripper_base_link" />
    <child
      link="Right_1_Link" />
    <axis
      xyz="0 0 1" />
    <limit
      lower="-3.1416"
      upper="3.1416"
      effort="0"
      velocity="0" />
  </joint>
  <link
    name="Right_2_Link">
    <inertial>
      <origin
        xyz="-0.00289936293533604 0.0248358974819604 1.83978616178828E-05"
        rpy="0 0 0" />
      <mass
        value="0.00657030740340088" />
      <inertia
        ixx="9.4018987076757E-07"
        ixy="1.56093395009947E-07"
        ixz="-5.34387801827842E-14"
        iyy="1.77897147303987E-07"
        iyz="2.43238111264308E-13"
        izz="1.03664567424634E-06" />
    </inertial>
    <visual>
      <origin
        xyz="0 0 0"
        rpy="0 0 0" />
      <geometry>
        <mesh
          filename="4dof_gripper_description/meshes/Right_2_Link.STL" />
      </geometry>
      <material
        name="">
        <color
          rgba="0.898039215686275 0.917647058823529 0.929411764705882 1" />
      </material>
    </visual>
    <collision>
      <origin
        xyz="0 0 0"
        rpy="0 0 0" />
      <geometry>
        <mesh
          filename="4dof_gripper_description/meshes/Right_2_Link.STL" />
      </geometry>
    </collision>
  </link>
  <joint
    name="Right_2"
    type="revolute">
    <origin
      xyz="0.0499999999999749 0 0"
      rpy="3.14159265358979 0 1.5707963267949" />
    <parent
      link="Right_1_Link" />
    <child
      link="Right_2_Link" />
    <axis
      xyz="0 0 1" />
    <limit
      lower="-3.1416"
      upper="3.1416"
      effort="0"
      velocity="0" />
  </joint>
  <link
    name="R_TouchSensor_link">
    <inertial>
      <origin
        xyz="-0.00202376595001491 2.12603213266098E-07 -0.0264861041562325"
        rpy="0 0 0" />
      <mass
        value="0.124388957693126" />
      <inertia
        ixx="3.22977251728855E-05"
        ixy="-1.3218319761948E-14"
        ixz="-8.25543029410075E-07"
        iyy="3.61487480611386E-05"
        iyz="2.20679027662246E-13"
        izz="3.00247512991208E-05" />
    </inertial>
    <visual>
      <origin
        xyz="0 0 0"
        rpy="0 0 0" />
      <geometry>
        <mesh
          filename="4dof_gripper_description/meshes/R_TouchSensor_link.STL" />
      </geometry>
      <material
        name="">
        <color
          rgba="0.898039215686275 0.917647058823529 0.929411764705882 1" />
      </material>
    </visual>
    <collision>
      <origin
        xyz="0 0 0"
        rpy="0 0 0" />
      <geometry>
        <mesh
          filename="4dof_gripper_description/meshes/R_TouchSensor_link.STL" />
      </geometry>
    </collision>
  </link>
  <joint
    name="R_TouchSensor"
    type="fixed">
    <origin
      xyz="-0.020167 0.067069 0"
      rpy="1.5708 0 2.618" />
    <parent
      link="Right_2_Link" />
    <child
      link="R_TouchSensor_link" />
    <axis
      xyz="0 0 0" />
  </joint>
  <link name="grasp_convenient_link"/>
  <joint name="grasp_convenient_joint" type="fixed">
    <origin rpy="0 -1.57079 0" xyz="0 0 0.14"/>
    <parent link="gripper_base_link"/>
    <child link="grasp_convenient_link"/>
  </joint>

<!-- eye-in-hand camera -->
  <joint name="realsense_hand_joint" type="fixed">
    <origin rpy="2.12574149 -1.55582192  2.58286879" xyz="0.04028231  0.07736792  0.01266915"/>
    <parent link="xmate3_link7"/>
    <child link="camera_hand_color_frame"/>
  </joint>
  <link name="camera_hand_link">
    <visual>
      <origin rpy="1.5707963267948966 0 1.5707963267948966" xyz="0.00987 -0.02 -0.02"/>
      <geometry>
        <mesh filename="realsense2_description/meshes/d415.stl"/>
      </geometry>
      <material name="aluminum"/>
    </visual>
    <collision>
      <origin rpy="0 0 0" xyz="0 -0.02 0"/>
      <geometry>
        <box size="0.02005 0.099 0.023"/>
      </geometry>
    </collision>
    <inertial>
      <mass value="0.564"/>
      <origin xyz="0 0 0"/>
      <inertia ixx="0.003881243" ixy="0.0" ixz="0.0" iyy="0.000498940" iyz="0.0" izz="0.003879257"/>
    </inertial>
  </link>

  <!-- camera color joints and links -->
  <joint name="camera_hand_color_joint" type="fixed">
    <origin xyz="0 -0.015 0" rpy="0 0 0"/>
    <parent link="camera_hand_color_frame"/>
    <child link="camera_hand_link"/>
  </joint>
  <link name="camera_hand_color_frame"/>

  <joint name="camera_hand_color_optical_joint" type="fixed">
    <origin xyz="0 0 0" rpy="-1.571 -0.000 -1.571"/>
    <parent link="camera_hand_color_frame"/>
    <child link="camera_hand_color_optical_frame"/>
  </joint>
  <link name="camera_hand_color_optical_frame"/>
  <!-- Only used when processing real point cloud since it requires camera_hand_depth_optical_frame -->
  <joint name="camera_hand_depth_optical_joint" type="fixed">
    <origin xyz="-0.000 -0.015 -0.000" rpy="-1.573 0.003 -1.576"/>
    <parent link="camera_hand_color_frame"/>
    <child link="camera_hand_depth_optical_frame"/>
  </joint>
  <link name="camera_hand_depth_optical_frame"/>
 
<!-- eye-on-base camera -->
  <joint name="realsense_base_joint" type="fixed">
    <!-- <origin rpy="-0.026407443096889277 0.5109299626903319 0.4578676884689042" xyz="0.05793063 -0.50792133 0.65201918"/> -->
    <origin rpy="-0.01909744  0.51414666  0.46018937" xyz="0.05880015 -0.51058289  0.64973008"/>
    <parent link="xmate3_base"/>
    <child link="camera_base_color_frame"/>
  </joint>
  <link name="camera_base_color_frame"/>

  <joint name="camera_base_color_joint" type="fixed">
    <origin xyz="0 -0.015 0" rpy="0.001 0.005 -0.012"/>
    <child link="camera_base_link"/>
    <parent link="camera_base_color_frame"/>
  </joint>
  <link name="camera_base_link">
    <visual>
      <origin rpy="1.5707963267948966 0 1.5707963267948966" xyz="0.00987 -0.02 -0.02"/>
      <geometry>
        <mesh filename="realsense2_description/meshes/d415.stl"/>
      </geometry>
      <material name="aluminum"/>
    </visual>
    <collision>
      <origin rpy="0 0 0" xyz="0 -0.02 0"/>
      <geometry>
        <box size="0.02005 0.099 0.023"/>
      </geometry>
    </collision>
    <inertial>
      <mass value="0.564"/>
      <origin xyz="0 0 0"/>
      <inertia ixx="0.003881243" ixy="0.0" ixz="0.0" iyy="0.000498940" iyz="0.0" izz="0.003879257"/>
    </inertial>
  </link>
  <joint name="camera_base_color_optical_joint" type="fixed">
    <origin xyz="0 0 0" rpy="-1.571 -0.000 -1.571"/>
    <parent link="camera_base_color_frame"/>
    <child link="camera_base_color_optical_frame"/>
  </joint>
  <link name="camera_base_color_optical_frame"/>
  <!-- Only used when processing real point cloud since it requires camera_base_depth_optical_frame -->
  <joint name="camera_base_depth_optical_joint" type="fixed">
    <origin xyz="-0.000 -0.015 -0.000" rpy="-1.576 0.001 -1.583"/>
    <parent link="camera_base_color_frame"/>
    <child link="camera_base_depth_optical_frame"/>
  </joint>
  <link name="camera_base_depth_optical_frame"/>

</robot>
